<robot xmlns:xacro="http://www.ros.org/wiki/xacro" name="my_robot2">
	<material name="red">
		<color rgba="1 0 0 1" />
	</material>
	<material name="black">
		<color rgba="0 0 0 1"/>
	</material>
	<material name="blue">
		<color rgba="0 0 1 0.7"/>
	</material>
	<material name="white">
		<color rgba="1 1 1 1"/>
	</material>

	<xacro:macro name="strip_xacro" params="w">
		<link name="strip${1+(w-1)*4}">
			<visual>
				<geometry>
					<box size="0.2 0.05 0.01"/>
				</geometry>
				<origin rpy="1.57 1.57 0" xyz="0 0 0"/>
				<material name="blue"/>
			</visual>
		</link>
		<link name="strip${2+(w-1)*4}">
			<visual>
				<geometry>
					<box size="0.2 0.05 0.01"/>
				</geometry>
				<origin rpy="1.57 1.57 0" xyz="0 0 0"/>
				<material name="blue"/>
			</visual>
		</link>
		<link name="strip${3+(w-1)*4}">
			<visual>
				<geometry>
					<box size="0.2 0.05 0.01"/>
				</geometry>
				<origin rpy="0 1.57 0" xyz="0 0 0"/>
				<material name="blue"/>
			</visual>
		</link>
		<link name="strip${4+(w-1)*4}">
			<visual>
				<geometry>
					<box size="0.2 0.05 0.01"/>
				</geometry>
				<origin rpy="0 1.57 0" xyz="0 0 0"/>
				<material name="blue"/>
			</visual>
		</link>
	</xacro:macro>

	<xacro:macro name="strip_joints_xacro" params="w">
		<joint name="strip${1+(w-1)*4}_to_wheel${w}" type="fixed">
			<parent link="wheel${w}"/>
			<child link="strip${1+(w-1)*4}"/>
			<origin rpy="0 0 0" xyz="0 0.25 0"/>
			<limit effort="100" velocity="100"/>
		</joint>
		<joint name="strip${2+(w-1)*4}_to_wheel${w}" type="fixed">
			<parent link="wheel${w}"/>
			<child link="strip${2+(w-1)*4}"/>
			<origin rpy="0 0 0" xyz="0 -0.25 0"/>
			<limit effort="100" velocity="100"/>
		</joint>
		<joint name="strip${3+(w-1)*4}_to_wheel${w}" type="fixed">
			<parent link="wheel${w}"/>
			<child link="strip${3+(w-1)*4}"/>
			<origin rpy="0 0 0" xyz="0.25 0 0"/>
			<limit effort="100" velocity="100"/>
		</joint>
		<joint name="strip${4+(w-1)*4}_to_wheel${w}" type="fixed">
			<parent link="wheel${w}"/>
			<child link="strip${4+(w-1)*4}"/>
			<origin rpy="0 0 0" xyz="-0.25 0 0"/>
			<limit effort="100" velocity="100"/>
		</joint>
	</xacro:macro>

	<xacro:macro name="rims" params="w">
		<link name="rim${w}">
			<visual>
				<geometry>
					<cylinder length="0.205" radius="0.1"/>
				</geometry>
				<material name="white"/>
			</visual>
		</link>
		<joint name="rim${w}_to_wheel${w}" type="fixed">
			<parent link="wheel${w}"/>
			<child link="rim${w}"/>
			<origin rpy="0 0 0" xyz="0 0 0"/>
		</joint>
	</xacro:macro>

	<link name="base_link">
		<visual>
			<geometry>
				<box size="1.5 0.75 0.3" />
			</geometry>
			<material name="red" />
		</visual>
	</link>

	<link name="head_link">
		<visual>
			<geometry>
				<sphere radius="0.3"/>
			</geometry>
			<material name="black"/>
		</visual>
	</link>
	<joint name="head_to_base" type="fixed">
		<parent link="base_link"/>
		<child link="head_link"/>
		<origin rpy="0 0 0" xyz="-0.45 0 0.15"/>
	</joint>

	<link name="wheel1">
		<visual>
			<geometry>
				<cylinder length="0.20" radius="0.25"/>
			</geometry>
			<material name="black"/>
		</visual>
	</link>
	<joint name="base_to_wheel1" type="continuous">
		<axis xyz="0 0 1"/>
		<origin rpy="1.57 0 0" xyz="-0.75 -0.485 0"/>
		<parent link="base_link"/>
		<child link="wheel1"/>
		<limit effort="100" velocity="100"/>
	</joint>
	<xacro:strip_xacro w="1"/>
	<xacro:strip_joints_xacro w="1"/>
	<xacro:rims w="1"/>

	<link name="wheel2">
		<visual>
			<geometry>
				<cylinder length="0.20" radius="0.25"/>
			</geometry>
			<material name="black"/>
		</visual>
	</link>
	<joint name="base_to_wheel2" type="continuous">
		<axis xyz="0 0 1"/>
		<origin rpy="1.57 0 0" xyz="0 -0.485 0"/>
		<parent link="base_link"/>
		<child link="wheel2"/>
		<limit effort="100" velocity="100"/>
	</joint>
	<xacro:strip_xacro w="2"/>
	<xacro:strip_joints_xacro w="2"/>
	<xacro:rims w="2"/>

	<link name="wheel3">
		<visual>
			<geometry>
				<cylinder length="0.20" radius="0.25"/>
			</geometry>
			<material name="black"/>
		</visual>
	</link>
	<joint name="base_to_wheel3" type="continuous">
		<axis xyz="0 0 1"/>
		<origin rpy="1.57 0 0" xyz="0.75 -0.485 0"/>
		<parent link="base_link"/>
		<child link="wheel3"/>
		<limit effort="100" velocity="100"/>
	</joint>
	<xacro:strip_xacro w="3"/>
	<xacro:strip_joints_xacro w="3"/>
	<xacro:rims w="3"/>

	<link name="wheel4">
		<visual>
			<geometry>
				<cylinder length="0.20" radius="0.25"/>
			</geometry>
			<material name="black"/>
		</visual>
	</link>
	<joint name="base_to_wheel4" type="continuous">
		<axis xyz="0 0 1"/>
		<origin rpy="1.57 0 0" xyz="0.75 0.485 0"/>
		<parent link="base_link"/>
		<child link="wheel4"/>
		<limit effort="100" velocity="100"/>
	</joint>
	<xacro:strip_xacro w="4"/>
	<xacro:strip_joints_xacro w="4"/>
	<xacro:rims w="4"/>

	<link name="wheel5">
		<visual>
			<geometry>
				<cylinder length="0.20" radius="0.25"/>
			</geometry>
			<material name="black"/>
		</visual>
	</link>
	<joint name="base_to_wheel5" type="continuous">
		<axis xyz="0 0 1"/>
		<origin rpy="1.57 0 0" xyz="0 0.485 0"/>
		<parent link="base_link"/>
		<child link="wheel5"/>
		<limit effort="100" velocity="100"/>
	</joint>
	<xacro:strip_xacro w="5"/>
	<xacro:strip_joints_xacro w="5"/>
	<xacro:rims w="5"/>

	<link name="wheel6">
		<visual>
			<geometry>
				<cylinder length="0.20" radius="0.25"/>
			</geometry>
			<material name="black"/>
		</visual>
	</link>
	<joint name="base_to_wheel6" type="continuous">
		<axis xyz="0 0 1"/>
		<origin rpy="1.57 0 0" xyz="-0.75 0.485 0"/>
		<parent link="base_link"/>
		<child link="wheel6"/>
		<limit effort="100" velocity="100"/>
	</joint>
	<xacro:strip_xacro w="6"/>
	<xacro:strip_joints_xacro w="6"/>
	<xacro:rims w="6"/>

</robot>
