<robot
  name="Chassis_assembly_URDF">
  <link
    name="base_link">
    <inertial>
      <origin
        xyz="0.0 0.0 0.0"
        rpy="0 0 0" />
      <mass
        value="0.3794" />
      <inertia
        ixx="0"
        ixy="0"
        ixz="0"
        iyy="0"
        iyz="0"
        izz="0" />
    </inertial>
    <visual>
      <origin
        xyz="0 0 0"
        rpy="0 0 0" />
      <geometry>
        <mesh
          filename="file:///home/ayushgarg/catkin_ws/src/Chassis_assembly_URDF/meshes/base_link.STL" />
      </geometry>
      <material
        name="">
        <color
          rgba="0.79216 0.81961 0.93333 1" />
      </material>
    </visual>
    <collision>
      <origin
        xyz="0 0 0"
        rpy="0 0 0" />
      <geometry>
        <mesh
          filename="file:///home/ayushgarg/catkin_ws/src/Chassis_assembly_URDF/meshes/base_link.STL" />
      </geometry>
    </collision>
  </link>
  <link
    name="child_Link">
    <inertial>
      <origin
        xyz="0.0 0.0 0.0"
        rpy="0 0 0" />
      <mass
        value="2.7022" />
      <inertia
        ixx="0"
        ixy="0"
        ixz="0"
        iyy="0"
        iyz="0"
        izz="0" />
    </inertial>
    <visual>
      <origin
        xyz="0 0 0"
        rpy="0 0 0" />
      <geometry>
        <mesh
          filename="file:///home/ayushgarg/catkin_ws/src/Chassis_assembly_URDF/meshes/child_Link.STL" />
      </geometry>
      <material
        name="">
        <color
          rgba="0.75294 0.75294 0.75294 1" />
      </material>
    </visual>
    <collision>
      <origin
        xyz="0 0 0"
        rpy="0 0 0" />
      <geometry>
        <mesh
          filename="file:///home/ayushgarg/catkin_ws/src/Chassis_assembly_URDF/meshes/child_Link.STL" />
      </geometry>
    </collision>
  </link>
  <joint
    name="base_to_child"
    type="continuous">
    <origin
      xyz="0.0 0 0"
      rpy="0 0 0" />
    <parent
      link="base_link" />
    <child
      link="child_Link" />
    <axis
      xyz="0 0 0" />
  </joint>
</robot>
